---
title: "高频手写初级04：柯里化，PromiseA+"
date: 2021-02-11 16:55:17
tags:
  - 面试
  - 手写实现
---

<!--banner-pic|sticker|content-img|content-img-half-->
<img class="banner-pic" src="http://oss.slybootslion.com/blog/v2-8afd27bed877754d3045acd1c832f9d4_r.jpg?x-oss-process=image/auto-orient,1/quality,q_80/watermark,text_c2x5Ym9vdHNsaW9u,color_ffffff,size_40,shadow_70,t_74,x_10,y_10"/>


### 柯里化

```js
function curry (fun, ...args) {
  const len = fun.length
  return (...args1) => {
    const arr = [...args, ...args1]
    if (arr.length < len) {
      return curry(fun, ...arr)
    } else {
      return fun(...arr)
    }
  }
}
```

### Promise A+

```js
const STATUS = {
  PENDING: 'PENDING',
  FULFILLED: 'FULFILLED',
  REJECTED: 'REJECTED'
}

function resolvePromise (x, promise2, resolve, reject) {
  // x如果是promise，就采用x的状态（成功或者失败）
  // If promise and x refer to the same object, reject promise with a TypeError as the reason.
  if (x === promise2) {
    return reject(new TypeError('promise被循环引用（Chaining cycle detected for promise）'))
  }

  if ((typeof x === 'object' && x !== null) || typeof x === 'function') {
    let called = false
    try {
      let then = x.then
      if (typeof then === 'function') {
        // x是一个promise对象
        // 调用返回的promise 用它的结果 作为下一次then的结果
        then.call(x, function (y) {
          if (called) return
          called = true
          // 递归调用，直到它是一个非promise对象为止
          resolvePromise(y, promise2, resolve, reject)
        }, function (r) {
          if (called) return
          called = true
          reject(r)
        })
      } else {
        // x是一个普通对象
        resolve(x)
      }
    } catch (err) {
      if (called) return
      called = true
      reject(err)
    }
  } else {
    // x如果是普通值，直接调用resolve
    resolve(x)
  }
}

class MyPromise {
  constructor (executor) {
    this.status = STATUS.PENDING
    this.value = undefined
    this.reason = undefined
    this.onResolvedCallbacks = []
    this.onRejectedCallbacks = []

    const resolve = (value) => {
      if (this.status === STATUS.PENDING) {
        this.status = STATUS.FULFILLED
        this.value = value
        this.onResolvedCallbacks.forEach(fn => fn())
      }
    }

    const reject = (reason) => {
      if (this.status === STATUS.PENDING) {
        this.status = STATUS.REJECTED
        this.reason = reason
        this.onRejectedCallbacks.forEach(fn => fn())
      }
    }

    try {
      executor(resolve, reject)
    } catch (err) {
      reject(err)
    }
  }

  then (onFulfilled, onRejected) {
    // Both onFulfilled and onRejected are optional arguments:
    // If onFulfilled is not a function, it must be ignored.
    // If onRejected is not a function, it must be ignored.
    onFulfilled = typeof onFulfilled === 'function' ? onFulfilled : x => x
    onRejected = typeof onRejected === 'function' ? onRejected : err => {
      throw err
    }

    // then must return a promise
    let promise2 = new Promise((resolve, reject) => {
      if (this.status === STATUS.FULFILLED) {
        setTimeout(() => {
          try {
            const x = onFulfilled(this.value)
            resolvePromise(x, promise2, resolve, reject)
          } catch (err) {
            reject(err)
          }
        }, 0)
      }
      if (this.status === STATUS.REJECTED) {
        setTimeout(() => {
          try {
            const x = onRejected(this.reason)
            resolvePromise(x, promise2, resolve, reject)
          } catch (err) {
            reject(err)
          }
        }, 0)
      }
      if (this.status === STATUS.PENDING) {
        this.onResolvedCallbacks.push(() => {
          setTimeout(() => {
            try {
              const x = onFulfilled(this.value)
              resolvePromise(x, promise2, resolve, reject)
            } catch (err) {
              reject(err)
            }
          }, 0)
        })
        this.onRejectedCallbacks.push(() => {
          setTimeout(() => {
            try {
              const x = onRejected(this.reason)
              resolvePromise(x, promise2, resolve, reject)
            } catch (err) {
              reject(err)
            }
          }, 0)
        })
      }
    })

    return promise2
  }
}
```


<!-- more -->
